Workbook

Sheet README
A1: Data-recording workbook: Option A (full mechanistic trial) and Option B (minimum add-on)
A2: Rice cv. IR-64 | endophyte treatments Control, IS-06, IS-05, C4-5 | NaCl 0, 50, 100 and 150 mM (same 4-tier format as the first trial) | 4 replicate pots each (64 pots)
A4: HOW TO USE
A5: Yellow cells | B5: Enter your raw readings here (one row per pot; enter the mean of the 3 plants in the pot unless the column says otherwise).
A6: White cells with numbers | B6: Formulas. Do not type over them; they calculate automatically from your readings.
A7: Grey row "EX" | B7: Worked example with realistic dummy values to show the expected format. Delete or ignore it; it is excluded from the Summary sheet.
A8: Blue text | B8: Example values only (not real data).
A9: Column headers | B9: Hover over a header with a red corner for the method, wavelength and units.
A11: WHICH SHEETS TO USE
A12: Option A (full) | B12: Layout, A1_Growth_Intervals, A2_Growth_Harvest, A3_Pigments, A4_Osmo_Oxidative, A5_Enzymes, A6_Ions, A7_GasExchange (optional), Std_Curves, Summary.
A13: Option B (minimum) | B13: Layout, B_Minimal, Std_Curves (proline block), Summary. Same 64 pots; B is a subset of A, so if you run A you do not need B separately.
A14: Instruments | B14: See sheet "Instruments": what the progress report confirms you have, and what you must confirm or outsource.
A15: Timeline | B15: See sheet "Timeline" for the day-by-day plan (about 45 days in the polyhouse + 2-3 weeks of lab assays).
A17: IMPORTANT DESIGN NOTES
A18: Replicates | B18: Record every replicate pot separately. Do NOT enter only means: replicate-level data are what allow ANOVA, MANOVA and correct SDs.
A19: Salt timing | B19: Write down the exact day saline irrigation starts (sheet Timeline). In the earlier trial the methods said 15 DAS but germination fell with salt, which reviewers will question.
A20: Fresh vs dry basis | B20: Biochemical values are calculated per g fresh weight (FW) for leaf assays and per g dry weight (DW) for ions, as is standard. Record the exact tissue mass for every sample.
A21: Same leaf, same day | B21: Take RWC, electrolyte leakage, pigments, MDA, H2O2, proline and enzyme samples from comparable fully expanded leaves on the same day, at the same time of morning.
A22: Enzymes | B22: Extract on ice in cold phosphate buffer and assay the same day (or store at -20 °C / -80 °C if available). Enter protein (mg/mL) of the SAME enzyme extract to get specific activity.
A23: Randomization | B23: Bench positions in "Layout" were randomized (completely randomized design, random seed 2026). Place pots accordingly and re-randomize weekly if possible.

Sheet Instruments
A1: Instruments: confirmed in your progress report vs. needed for the new parameters
A2: Confirmed = explicitly used in the progress report (Jul-Dec 2025). Confirm = not mentioned in the report; check with your lab / department.
A4: Parameter | B4: Option | C4: Method (reference) | D4: Instrument needed | E4: In progress report? | F4: If not available
A5: Plant height, leaf number | B5: A | C5: Ruler / count at 15, 25, 35, 45 DAS | D5: Scale, ruler | E5: Confirmed (root/shoot lengths measured) | F5: -
A6: Shoot & root fresh weight | B6: A, B | C6: Gravimetric | D6: Analytical balance | E6: Confirmed | F6: -
A7: Shoot & root dry weight | B7: A, B | C7: Oven-dry 70 °C, 72 h to constant weight | D7: Hot-air oven | E7: Confirm (not mentioned) | F7: Use the glassware-drying oven of any microbiology lab; 60-70 °C is enough
A8: Leaf area | B8: A | C8: Scan/photograph leaves on a white sheet with a scale; measure in ImageJ (free) | D8: Flatbed scanner or phone camera | E8: Confirm | F8: Length x max width x 0.75 (rice leaf factor) as a fallback
A9: Root volume, surface area, branching | B9: A (optional) | C9: Scan washed roots in water tray; RhizoVision Explorer (free) or WinRHIZO | D9: Flatbed scanner (600 dpi) | E9: Confirm | F9: Root volume by water displacement in a measuring cylinder; drop surface area/branching and state as limitation
A10: Chlorophyll a, b, total, carotenoids | B10: A | C10: DMSO 60 °C (Hiscox & Israelstam 1979); Arnon (1949) as before; carotenoids Wellburn (1994) DMSO equation at 480 nm | D10: UV-Vis spectrophotometer, water bath | E10: Confirmed | F10: -
A11: Relative water content | B11: A | C11: FW, turgid weight (4 h in water, dark), DW (Barrs & Weatherley 1962) | D11: Analytical balance, oven | E11: Balance confirmed; oven confirm | F11: -
A12: Electrolyte leakage | B12: A | C12: EC of leaf discs in deionized water, before and after boiling (Lutts et al. 1996) | D12: Conductivity (EC) meter | E12: Confirm (not mentioned) | F12: Borrow from a soil science / chemistry lab; it is a small handheld meter
A13: Proline | B13: A, B | C13: Acid-ninhydrin, toluene phase, A520 (Bates et al. 1973) | D13: UV-Vis spectrophotometer, water bath, centrifuge | E13: Confirmed | F13: -
A14: Soluble sugars, soluble protein | B14: A | C14: Anthrone A620; Lowry A660 (as before) | D14: UV-Vis spectrophotometer | E14: Confirmed | F14: -
A15: MDA (lipid peroxidation) | B15: A, B | C15: TBA, A532 - A600, ε = 155 mM-1 cm-1 (Heath & Packer 1968) | D15: UV-Vis spectrophotometer, water bath, centrifuge | E15: Confirmed | F15: -
... A25: Incubation, culture, inoculum | B25: A, B | C25: Nutrient broth, 37 °C; seed bacterization 30 min, ~10^8 CFU/mL | D25: Bacteriological incubator, laminar flow, autoclave | E25: Confirmed (incubator) | F25: -
A27: Method references are given for planning; DOIs will be verified when the methods are added to the manuscript.

Sheet Layout
A1: Pot layout: 4 inoculation treatments x 4 NaCl levels (0, 50, 100, 150 mM) x 4 replicates = 64 pots (CRD)
A2: Fill the yellow cells on the day of each event. Bench positions randomized with seed 2026.
A4: Pot ID | B4: Treatment | C4: Inoculant | D4: NaCl (mM) | E4: Rep | F4: Bench position | G4: Sowing date | H4: Seeds sown | I4: Seedlings emerged (7 DAS) | J4: Emergence % | K4: Plants after thinning | L4: Plants surviving at harvest | M4: Survival % | N4: Notes
A5: P01 | B5: Control | 0 mM | C5: Control | D5: 0 | E5: 1 | F5: 60 | J5: =IF(OR(H5="",I5=""),"",I5/H5*100) | M5: =IF(OR(K5="",L5=""),"",L5/K5*100)
A6: P02 | B6: Control | 0 mM | C6: Control | D6: 0 | E6: 2 | F6: 46 | J6: =IF(OR(H6="",I6=""),"",I6/H6*100) | M6: =IF(OR(K6="",L6=""),"",L6/K6*100)
A7: P03 | B7: Control | 0 mM | C7: Control | D7: 0 | E7: 3 | F7: 2 | J7: =IF(OR(H7="",I7=""),"",I7/H7*100) | M7: =IF(OR(K7="",L7=""),"",L7/K7*100)
A8: P04 | B8: Control | 0 mM | C8: Control | D8: 0 | E8: 4 | F8: 31 | J8: =IF(OR(H8="",I8=""),"",I8/H8*100) | M8: =IF(OR(K8="",L8=""),"",L8/K8*100)
A9: P05 | B9: Control | 50 mM | C9: Control | D9: 50 | E9: 1 | F9: 59 | J9: =IF(OR(H9="",I9=""),"",I9/H9*100) | M9: =IF(OR(K9="",L9=""),"",L9/K9*100)
A10: P06 | B10: Control | 50 mM | C10: Control | D10: 50 | E10: 2 | F10: 4 | J10: =IF(OR(H10="",I10=""),"",I10/H10*100) | M10: =IF(OR(K10="",L10=""),"",L10/K10*100)
A11: P07 | B11: Control | 50 mM | C11: Control | D11: 50 | E11: 3 | F11: 44 | J11: =IF(OR(H11="",I11=""),"",I11/H11*100) | M11: =IF(OR(K11="",L11=""),"",L11/K11*100)
A12: P08 | B12: Control | 50 mM | C12: Control | D12: 50 | E12: 4 | F12: 41 | J12: =IF(OR(H12="",I12=""),"",I12/H12*100) | M12: =IF(OR(K12="",L12=""),"",L12/K12*100)
A13: P09 | B13: Control | 100 mM | C13: Control | D13: 100 | E13: 1 | F13: 49 | J13: =IF(OR(H13="",I13=""),"",I13/H13*100) | M13: =IF(OR(K13="",L13=""),"",L13/K13*100)
A14: P10 | B14: Control | 100 mM | C14: Control | D14: 100 | E14: 2 | F14: 5 | J14: =IF(OR(H14="",I14=""),"",I14/H14*100) | M14: =IF(OR(K14="",L14=""),"",L14/K14*100)
A15: P11 | B15: Control | 100 mM | C15: Control | D15: 100 | E15: 3 | F15: 25 | J15: =IF(OR(H15="",I15=""),"",I15/H15*100) | M15: =IF(OR(K15="",L15=""),"",L15/K15*100)
A16: P12 | B16: Control | 100 mM | C16: Control | D16: 100 | E16: 4 | F16: 52 | J16: =IF(OR(H16="",I16=""),"",I16/H16*100) | M16: =IF(OR(K16="",L16=""),"",L16/K16*100)
... A68: P64 | B68: C4-5 | 150 mM | C68: C4-5 | D68: 150 | E68: 4 | F68: 16 | J68: =IF(OR(H68="",I68=""),"",I68/H68*100) | M68: =IF(OR(K68="",L68=""),"",L68/K68*100)

Sheet A1_Growth_Intervals
A1: Option A | Growth at defined intervals (mean of the 3 plants per pot)
A2: DAS = days after sowing.
A4: Design | F4: 15 DAS | H4: 25 DAS | J4: 35 DAS | L4: 45 DAS | N4: Growth rate
A5: Pot ID | B5: Treatment | C5: Inoculant | D5: NaCl (mM) | E5: Rep | F5: Height 15 DAS (cm) | G5: Leaves 15 DAS (no.) | H5: Height 25 DAS (cm) | I5: Leaves 25 DAS (no.) | J5: Height 35 DAS (cm) | K5: Leaves 35 DAS (no.) | L5: Height 45 DAS (cm) | M5: Leaves 45 DAS (no.) | N5: Height gain 15-45 DAS (cm/day)
A6: EX | B6: EXAMPLE (delete) | C6: EXAMPLE | D6: 150 | E6: 0 | F6: 14.2 | G6: 3 | H6: 19.8 | I6: 4 | J6: 24.1 | K6: 5 | L6: 28.6 | M6: 6 | N6: =IF(OR(F6="",L6=""),"",(L6-F6)/30) -> 0.48
A7: P01 | B7: Control | 0 mM | C7: Control | D7: 0 | E7: 1 | N7: =IF(OR(F7="",L7=""),"",(L7-F7)/30)
A8: P02 | B8: Control | 0 mM | C8: Control | D8: 0 | E8: 2 | N8: =IF(OR(F8="",L8=""),"",(L8-F8)/30)
A9: P03 | B9: Control | 0 mM | C9: Control | D9: 0 | E9: 3 | N9: =IF(OR(F9="",L9=""),"",(L9-F9)/30)
A10: P04 | B10: Control | 0 mM | C10: Control | D10: 0 | E10: 4 | N10: =IF(OR(F10="",L10=""),"",(L10-F10)/30)
A11: P05 | B11: Control | 50 mM | C11: Control | D11: 50 | E11: 1 | N11: =IF(OR(F11="",L11=""),"",(L11-F11)/30)
A12: P06 | B12: Control | 50 mM | C12: Control | D12: 50 | E12: 2 | N12: =IF(OR(F12="",L12=""),"",(L12-F12)/30)
A13: P07 | B13: Control | 50 mM | C13: Control | D13: 50 | E13: 3 | N13: =IF(OR(F13="",L13=""),"",(L13-F13)/30)
A14: P08 | B14: Control | 50 mM | C14: Control | D14: 50 | E14: 4 | N14: =IF(OR(F14="",L14=""),"",(L14-F14)/30)
A15: P09 | B15: Control | 100 mM | C15: Control | D15: 100 | E15: 1 | N15: =IF(OR(F15="",L15=""),"",(L15-F15)/30)
A16: P10 | B16: Control | 100 mM | C16: Control | D16: 100 | E16: 2 | N16: =IF(OR(F16="",L16=""),"",(L16-F16)/30)
A17: P11 | B17: Control | 100 mM | C17: Control | D17: 100 | E17: 3 | N17: =IF(OR(F17="",L17=""),"",(L17-F17)/30)
A18: P12 | B18: Control | 100 mM | C18: Control | D18: 100 | E18: 4 | N18: =IF(OR(F18="",L18=""),"",(L18-F18)/30)
... A70: P64 | B70: C4-5 | 150 mM | C70: C4-5 | D70: 150 | E70: 4 | N70: =IF(OR(F70="",L70=""),"",(L70-F70)/30)

Sheet A2_Growth_Harvest
A1: Option A | Harvest (45 DAS): biomass, roots, water status
A2: Per pot: enter the mean of the 3 plants (biomass per plant).
A4: Design | F4: Shoot | I4: Root | Q4: Relative water content | U4: Electrolyte leakage
A5: Pot ID | B5: Treatment | C5: Inoculant | D5: NaCl (mM) | E5: Rep | F5: Leaf area (cm2/plant) | G5: Shoot FW (g) | H5: Shoot DW (g) | I5: Root length (cm) | J5: Root FW (g) | K5: Root DW (g) | L5: Root/shoot ratio (DW) | M5: Root volume (cm3) | N5: Root surface area (cm2) | O5: Root tips (no.) | P5: Root forks / branches (no.) | Q5: RWC leaf FW (g) | R5: RWC turgid wt (g) | S5: RWC dry wt (g) | T5: RWC (%) | U5: EC1 (µS/cm) | V5: EC2 (µS/cm) | W5: Electrolyte leakage (%) | X5: Membrane stability index (%)
A6: EX | B6: EXAMPLE (delete) | C6: EXAMPLE | D6: 150 | E6: 0 | F6: 42.5 | G6: 3.12 | H6: 0.61 | I6: 9.4 | J6: 1.05 | K6: 0.18 | L6: =IF(OR(K6="",H6=""),"",K6/H6) -> 0.29508197 | M6: 1.1 | N6: 38 | O6: 410 | P6: 650 | Q6: 0.25 | R6: 0.292 | S6: 0.061 | T6: =IF(OR(Q6="",R6="",S6=""),"",(Q6-S6)/(R6-S6)*100) -> 81.818182 | U6: 48 | V6: 210 | W6: =IF(OR(U6="",V6=""),"",U6/V6*100) -> 22.857143 | X6: =IF(OR(U6="",V6=""),"",(1-U6/V6)*100) -> 77.142857
A7: P01 | B7: Control | 0 mM | C7: Control | D7: 0 | E7: 1 | L7: =IF(OR(K7="",H7=""),"",K7/H7) | T7: =IF(OR(Q7="",R7="",S7=""),"",(Q7-S7)/(R7-S7)*100) | W7: =IF(OR(U7="",V7=""),"",U7/V7*100) | X7: =IF(OR(U7="",V7=""),"",(1-U7/V7)*100)
A8: P02 | B8: Control | 0 mM | C8: Control | D8: 0 | E8: 2 | L8: =IF(OR(K8="",H8=""),"",K8/H8) | T8: =IF(OR(Q8="",R8="",S8=""),"",(Q8-S8)/(R8-S8)*100) | W8: =IF(OR(U8="",V8=""),"",U8/V8*100) | X8: =IF(OR(U8="",V8=""),"",(1-U8/V8)*100)
A9: P03 | B9: Control | 0 mM | C9: Control | D9: 0 | E9: 3 | L9: =IF(OR(K9="",H9=""),"",K9/H9) | T9: =IF(OR(Q9="",R9="",S9=""),"",(Q9-S9)/(R9-S9)*100) | W9: =IF(OR(U9="",V9=""),"",U9/V9*100) | X9: =IF(OR(U9="",V9=""),"",(1-U9/V9)*100)
A10: P04 | B10: Control | 0 mM | C10: Control | D10: 0 | E10: 4 | L10: =IF(OR(K10="",H10=""),"",K10/H10) | T10: =IF(OR(Q10="",R10="",S10=""),"",(Q10-S10)/(R10-S10)*100) | W10: =IF(OR(U10="",V10=""),"",U10/V10*100) | X10: =IF(OR(U10="",V10=""),"",(1-U10/V10)*100)
A11: P05 | B11: Control | 50 mM | C11: Control | D11: 50 | E11: 1 | L11: =IF(OR(K11="",H11=""),"",K11/H11) | T11: =IF(OR(Q11="",R11="",S11=""),"",(Q11-S11)/(R11-S11)*100) | W11: =IF(OR(U11="",V11=""),"",U11/V11*100) | X11: =IF(OR(U11="",V11=""),"",(1-U11/V11)*100)
A12: P06 | B12: Control | 50 mM | C12: Control | D12: 50 | E12: 2 | L12: =IF(OR(K12="",H12=""),"",K12/H12) | T12: =IF(OR(Q12="",R12="",S12=""),"",(Q12-S12)/(R12-S12)*100) | W12: =IF(OR(U12="",V12=""),"",U12/V12*100) | X12: =IF(OR(U12="",V12=""),"",(1-U12/V12)*100)
A13: P07 | B13: Control | 50 mM | C13: Control | D13: 50 | E13: 3 | L13: =IF(OR(K13="",H13=""),"",K13/H13) | T13: =IF(OR(Q13="",R13="",S13=""),"",(Q13-S13)/(R13-S13)*100) | W13: =IF(OR(U13="",V13=""),"",U13/V13*100) | X13: =IF(OR(U13="",V13=""),"",(1-U13/V13)*100)
A14: P08 | B14: Control | 50 mM | C14: Control | D14: 50 | E14: 4 | L14: =IF(OR(K14="",H14=""),"",K14/H14) | T14: =IF(OR(Q14="",R14="",S14=""),"",(Q14-S14)/(R14-S14)*100) | W14: =IF(OR(U14="",V14=""),"",U14/V14*100) | X14: =IF(OR(U14="",V14=""),"",(1-U14/V14)*100)
A15: P09 | B15: Control | 100 mM | C15: Control | D15: 100 | E15: 1 | L15: =IF(OR(K15="",H15=""),"",K15/H15) | T15: =IF(OR(Q15="",R15="",S15=""),"",(Q15-S15)/(R15-S15)*100) | W15: =IF(OR(U15="",V15=""),"",U15/V15*100) | X15: =IF(OR(U15="",V15=""),"",(1-U15/V15)*100)
A16: P10 | B16: Control | 100 mM | C16: Control | D16: 100 | E16: 2 | L16: =IF(OR(K16="",H16=""),"",K16/H16) | T16: =IF(OR(Q16="",R16="",S16=""),"",(Q16-S16)/(R16-S16)*100) | W16: =IF(OR(U16="",V16=""),"",U16/V16*100) | X16: =IF(OR(U16="",V16=""),"",(1-U16/V16)*100)
A17: P11 | B17: Control | 100 mM | C17: Control | D17: 100 | E17: 3 | L17: =IF(OR(K17="",H17=""),"",K17/H17) | T17: =IF(OR(Q17="",R17="",S17=""),"",(Q17-S17)/(R17-S17)*100) | W17: =IF(OR(U17="",V17=""),"",U17/V17*100) | X17: =IF(OR(U17="",V17=""),"",(1-U17/V17)*100)
A18: P12 | B18: Control | 100 mM | C18: Control | D18: 100 | E18: 4 | L18: =IF(OR(K18="",H18=""),"",K18/H18) | T18: =IF(OR(Q18="",R18="",S18=""),"",(Q18-S18)/(R18-S18)*100) | W18: =IF(OR(U18="",V18=""),"",U18/V18*100) | X18: =IF(OR(U18="",V18=""),"",(1-U18/V18)*100)
... A70: P64 | B70: C4-5 | 150 mM | C70: C4-5 | D70: 150 | E70: 4 | L70: =IF(OR(K70="",H70=""),"",K70/H70) | T70: =IF(OR(Q70="",R70="",S70=""),"",(Q70-S70)/(R70-S70)*100) | W70: =IF(OR(U70="",V70=""),"",U70/V70*100) | X70: =IF(OR(U70="",V70=""),"",(1-U70/V70)*100)

Sheet Std_Curves
A1: Standard curves (absorbance = slope x concentration + intercept)
A2: Enter absorbance of each standard. Slope, intercept and R² update automatically and feed the assay sheets.
A4: Proline (µg/mL) at 520 nm | D4: H2O2 (µmol/mL) at 390 nm | G4: BSA protein (µg/mL) at 660 nm | J4: Glucose (µg/mL) at 620 nm
A5: Concentration | B5: Absorbance | D5: Concentration | E5: Absorbance | G5: Concentration | H5: Absorbance | J5: Concentration | K5: Absorbance
A6: 0 | D6: 0 | G6: 0 | J6: 0
A7: 5 | D7: 0.1 | G7: 40 | J7: 20
A8: 10 | D8: 0.2 | G8: 80 | J8: 40
A9: 20 | D9: 0.4 | G9: 120 | J9: 60
A10: 30 | D10: 0.6 | G10: 160 | J10: 80
A11: 40 | D11: 0.8 | G11: 200 | J11: 100
A13: Slope | B13: =IFERROR(SLOPE(B6:B11,A6:A11),"") | D13: Slope | E13: =IFERROR(SLOPE(E6:E11,D6:D11),"") | G13: Slope | H13: =IFERROR(SLOPE(H6:H11,G6:G11),"") | J13: Slope | K13: =IFERROR(SLOPE(K6:K11,J6:J11),"")
A14: Intercept | B14: =IFERROR(INTERCEPT(B6:B11,A6:A11),"") | D14: Intercept | E14: =IFERROR(INTERCEPT(E6:E11,D6:D11),"") | G14: Intercept | H14: =IFERROR(INTERCEPT(H6:H11,G6:G11),"") | J14: Intercept | K14: =IFERROR(INTERCEPT(K6:K11,J6:J11),"")
A15: R² | B15: =IFERROR(RSQ(B6:B11,A6:A11),"") | D15: R² | E15: =IFERROR(RSQ(E6:E11,D6:D11),"") | G15: R² | H15: =IFERROR(RSQ(H6:H11,G6:G11),"") | J15: R² | K15: =IFERROR(RSQ(K6:K11,J6:J11),"")
A17: Check: R² should be ≥ 0.99. Re-run any standard curve with each new batch of reagent.

Sheet A3_Pigments
A1: Option A | Photosynthetic pigments (DMSO extraction, 60 °C, 30 min)
A2: Chl by Arnon (1949) equations as in the earlier trial; carotenoids by the Wellburn (1994) DMSO equation at 480 nm.
A4: Design | F4: Sample | H4: Absorbance | K4: Concentration in extract (mg/L) | N4: Content (mg/g FW)
A5: Pot ID | B5: Treatment | C5: Inoculant | D5: NaCl (mM) | E5: Rep | F5: Leaf FW (g) | G5: DMSO volume (mL) | H5: A663 | I5: A645 | J5: A480 | K5: Chl a (mg/L) | L5: Chl b (mg/L) | M5: Carotenoids (mg/L) | N5: Chl a (mg/g FW) | O5: Chl b (mg/g FW) | P5: Total Chl (mg/g FW) | Q5: Carotenoids (mg/g FW) | R5: Chl a/b ratio
A6: EX | B6: EXAMPLE (delete) | C6: EXAMPLE | D6: 150 | E6: 0 | F6: 0.1 | G6: 5 | H6: 0.652 | I6: 0.248 | J6: 0.41 | K6: =IF(OR(H6="",I6=""),"",12.7*H6-2.69*I6) -> 7.61328 | L6: =IF(OR(H6="",I6=""),"",22.9*I6-4.68*H6) -> 2.62784 | M6: =IF(OR(J6="",H6="",I6=""),"",(1000*J6-1.29*K6-53.78*L6)/220) -> 1.1766074 | N6: =IF(OR(K6="",F6="",G6=""),"",K6*G6/(1000*F6)) -> 0.380664 | O6: =IF(OR(L6="",F6="",G6=""),"",L6*G6/(1000*F6)) -> 0.131392 | P6: =IF(OR(N6="",O6=""),"",N6+O6) -> 0.512056 | Q6: =IF(OR(M6=""),"",M6*G6/(1000*F6)) -> 0.058830371 | R6: =IF(OR(N6="",O6=""),"",N6/O6) -> 2.8971627
A7: P01 | B7: Control | 0 mM | C7: Control | D7: 0 | E7: 1 | K7: =IF(OR(H7="",I7=""),"",12.7*H7-2.69*I7) | L7: =IF(OR(H7="",I7=""),"",22.9*I7-4.68*H7) | M7: =IF(OR(J7="",H7="",I7=""),"",(1000*J7-1.29*K7-53.78*L7)/220) | N7: =IF(OR(K7="",F7="",G7=""),"",K7*G7/(1000*F7)) | O7: =IF(OR(L7="",F7="",G7=""),"",L7*G7/(1000*F7)) | P7: =IF(OR(N7="",O7=""),"",N7+O7) | Q7: =IF(OR(M7=""),"",M7*G7/(1000*F7)) | R7: =IF(OR(N7="",O7=""),"",N7/O7)
A8: P02 | B8: Control | 0 mM | C8: Control | D8: 0 | E8: 2 | K8: =IF(OR(H8="",I8=""),"",12.7*H8-2.69*I8) | L8: =IF(OR(H8="",I8=""),"",22.9*I8-4.68*H8) | M8: =IF(OR(J8="",H8="",I8=""),"",(1000*J8-1.29*K8-53.78*L8)/220) | N8: =IF(OR(K8="",F8="",G8=""),"",K8*G8/(1000*F8)) | O8: =IF(OR(L8="",F8="",G8=""),"",L8*G8/(1000*F8)) | P8: =IF(OR(N8="",O8=""),"",N8+O8) | Q8: =IF(OR(M8=""),"",M8*G8/(1000*F8)) | R8: =IF(OR(N8="",O8=""),"",N8/O8)
A9: P03 | B9: Control | 0 mM | C9: Control | D9: 0 | E9: 3 | K9: =IF(OR(H9="",I9=""),"",12.7*H9-2.69*I9) | L9: =IF(OR(H9="",I9=""),"",22.9*I9-4.68*H9) | M9: =IF(OR(J9="",H9="",I9=""),"",(1000*J9-1.29*K9-53.78*L9)/220) | N9: =IF(OR(K9="",F9="",G9=""),"",K9*G9/(1000*F9)) | O9: =IF(OR(L9="",F9="",G9=""),"",L9*G9/(1000*F9)) | P9: =IF(OR(N9="",O9=""),"",N9+O9) | Q9: =IF(OR(M9=""),"",M9*G9/(1000*F9)) | R9: =IF(OR(N9="",O9=""),"",N9/O9)
A10: P04 | B10: Control | 0 mM | C10: Control | D10: 0 | E10: 4 | K10: =IF(OR(H10="",I10=""),"",12.7*H10-2.69*I10) | L10: =IF(OR(H10="",I10=""),"",22.9*I10-4.68*H10) | M10: =IF(OR(J10="",H10="",I10=""),"",(1000*J10-1.29*K10-53.78*L10)/220) | N10: =IF(OR(K10="",F10="",G10=""),"",K10*G10/(1000*F10)) | O10: =IF(OR(L10="",F10="",G10=""),"",L10*G10/(1000*F10)) | P10: =IF(OR(N10="",O10=""),"",N10+O10) | Q10: =IF(OR(M10=""),"",M10*G10/(1000*F10)) | R10: =IF(OR(N10="",O10=""),"",N10/O10)
A11: P05 | B11: Control | 50 mM | C11: Control | D11: 50 | E11: 1 | K11: =IF(OR(H11="",I11=""),"",12.7*H11-2.69*I11) | L11: =IF(OR(H11="",I11=""),"",22.9*I11-4.68*H11) | M11: =IF(OR(J11="",H11="",I11=""),"",(1000*J11-1.29*K11-53.78*L11)/220) | N11: =IF(OR(K11="",F11="",G11=""),"",K11*G11/(1000*F11)) | O11: =IF(OR(L11="",F11="",G11=""),"",L11*G11/(1000*F11)) | P11: =IF(OR(N11="",O11=""),"",N11+O11) | Q11: =IF(OR(M11=""),"",M11*G11/(1000*F11)) | R11: =IF(OR(N11="",O11=""),"",N11/O11)
A12: P06 | B12: Control | 50 mM | C12: Control | D12: 50 | E12: 2 | K12: =IF(OR(H12="",I12=""),"",12.7*H12-2.69*I12) | L12: =IF(OR(H12="",I12=""),"",22.9*I12-4.68*H12) | M12: =IF(OR(J12="",H12="",I12=""),"",(1000*J12-1.29*K12-53.78*L12)/220) | N12: =IF(OR(K12="",F12="",G12=""),"",K12*G12/(1000*F12)) | O12: =IF(OR(L12="",F12="",G12=""),"",L12*G12/(1000*F12)) | P12: =IF(OR(N12="",O12=""),"",N12+O12) | Q12: =IF(OR(M12=""),"",M12*G12/(1000*F12)) | R12: =IF(OR(N12="",O12=""),"",N12/O12)
A13: P07 | B13: Control | 50 mM | C13: Control | D13: 50 | E13: 3 | K13: =IF(OR(H13="",I13=""),"",12.7*H13-2.69*I13) | L13: =IF(OR(H13="",I13=""),"",22.9*I13-4.68*H13) | M13: =IF(OR(J13="",H13="",I13=""),"",(1000*J13-1.29*K13-53.78*L13)/220) | N13: =IF(OR(K13="",F13="",G13=""),"",K13*G13/(1000*F13)) | O13: =IF(OR(L13="",F13="",G13=""),"",L13*G13/(1000*F13)) | P13: =IF(OR(N13="",O13=""),"",N13+O13) | Q13: =IF(OR(M13=""),"",M13*G13/(1000*F13)) | R13: =IF(OR(N13="",O13=""),"",N13/O13)
A14: P08 | B14: Control | 50 mM | C14: Control | D14: 50 | E14: 4 | K14: =IF(OR(H14="",I14=""),"",12.7*H14-2.69*I14) | L14: =IF(OR(H14="",I14=""),"",22.9*I14-4.68*H14) | M14: =IF(OR(J14="",H14="",I14=""),"",(1000*J14-1.29*K14-53.78*L14)/220) | N14: =IF(OR(K14="",F14="",G14=""),"",K14*G14/(1000*F14)) | O14: =IF(OR(L14="",F14="",G14=""),"",L14*G14/(1000*F14)) | P14: =IF(OR(N14="",O14=""),"",N14+O14) | Q14: =IF(OR(M14=""),"",M14*G14/(1000*F14)) | R14: =IF(OR(N14="",O14=""),"",N14/O14)
A15: P09 | B15: Control | 100 mM | C15: Control | D15: 100 | E15: 1 | K15: =IF(OR(H15="",I15=""),"",12.7*H15-2.69*I15) | L15: =IF(OR(H15="",I15=""),"",22.9*I15-4.68*H15) | M15: =IF(OR(J15="",H15="",I15=""),"",(1000*J15-1.29*K15-53.78*L15)/220) | N15: =IF(OR(K15="",F15="",G15=""),"",K15*G15/(1000*F15)) | O15: =IF(OR(L15="",F15="",G15=""),"",L15*G15/(1000*F15)) | P15: =IF(OR(N15="",O15=""),"",N15+O15) | Q15: =IF(OR(M15=""),"",M15*G15/(1000*F15)) | R15: =IF(OR(N15="",O15=""),"",N15/O15)
A16: P10 | B16: Control | 100 mM | C16: Control | D16: 100 | E16: 2 | K16: =IF(OR(H16="",I16=""),"",12.7*H16-2.69*I16) | L16: =IF(OR(H16="",I16=""),"",22.9*I16-4.68*H16) | M16: =IF(OR(J16="",H16="",I16=""),"",(1000*J16-1.29*K16-53.78*L16)/220) | N16: =IF(OR(K16="",F16="",G16=""),"",K16*G16/(1000*F16)) | O16: =IF(OR(L16="",F16="",G16=""),"",L16*G16/(1000*F16)) | P16: =IF(OR(N16="",O16=""),"",N16+O16) | Q16: =IF(OR(M16=""),"",M16*G16/(1000*F16)) | R16: =IF(OR(N16="",O16=""),"",N16/O16)
A17: P11 | B17: Control | 100 mM | C17: Control | D17: 100 | E17: 3 | K17: =IF(OR(H17="",I17=""),"",12.7*H17-2.69*I17) | L17: =IF(OR(H17="",I17=""),"",22.9*I17-4.68*H17) | M17: =IF(OR(J17="",H17="",I17=""),"",(1000*J17-1.29*K17-53.78*L17)/220) | N17: =IF(OR(K17="",F17="",G17=""),"",K17*G17/(1000*F17)) | O17: =IF(OR(L17="",F17="",G17=""),"",L17*G17/(1000*F17)) | P17: =IF(OR(N17="",O17=""),"",N17+O17) | Q17: =IF(OR(M17=""),"",M17*G17/(1000*F17)) | R17: =IF(OR(N17="",O17=""),"",N17/O17)
A18: P12 | B18: Control | 100 mM | C18: Control | D18: 100 | E18: 4 | K18: =IF(OR(H18="",I18=""),"",12.7*H18-2.69*I18) | L18: =IF(OR(H18="",I18=""),"",22.9*I18-4.68*H18) | M18: =IF(OR(J18="",H18="",I18=""),"",(1000*J18-1.29*K18-53.78*L18)/220) | N18: =IF(OR(K18="",F18="",G18=""),"",K18*G18/(1000*F18)) | O18: =IF(OR(L18="",F18="",G18=""),"",L18*G18/(1000*F18)) | P18: =IF(OR(N18="",O18=""),"",N18+O18) | Q18: =IF(OR(M18=""),"",M18*G18/(1000*F18)) | R18: =IF(OR(N18="",O18=""),"",N18/O18)
... A70: P64 | B70: C4-5 | 150 mM | C70: C4-5 | D70: 150 | E70: 4 | K70: =IF(OR(H70="",I70=""),"",12.7*H70-2.69*I70) | L70: =IF(OR(H70="",I70=""),"",22.9*I70-4.68*H70) | M70: =IF(OR(J70="",H70="",I70=""),"",(1000*J70-1.29*K70-53.78*L70)/220) | N70: =IF(OR(K70="",F70="",G70=""),"",K70*G70/(1000*F70)) | O70: =IF(OR(L70="",F70="",G70=""),"",L70*G70/(1000*F70)) | P70: =IF(OR(N70="",O70=""),"",N70+O70) | Q70: =IF(OR(M70=""),"",M70*G70/(1000*F70)) | R70: =IF(OR(N70="",O70=""),"",N70/O70)

Sheet A4_Osmo_Oxidative
A1: Option A | Osmolytes and oxidative-stress markers (leaf, fresh weight basis)
A2: Standard curves are taken from sheet Std_Curves.
A4: Design | F4: Proline (Bates et al. 1973) | K4: MDA (Heath & Packer 1968) | P4: H2O2 (Velikova et al. 2000) | T4: Soluble sugars (anthrone) | Y4: Soluble protein (Lowry)
A5: Pot ID | B5: Treatment | C5: Inoculant | D5: NaCl (mM) | E5: Rep | F5: Pro leaf FW (g) | G5: Pro A520 | H5: Toluene (mL) | I5: Proline (µg/mL) | J5: Proline (µmol/g FW) | K5: MDA leaf FW (g) | L5: MDA extract (mL) | M5: A532 | N5: A600 | O5: MDA (nmol/g FW) | P5: H2O2 leaf FW (g) | Q5: H2O2 extract (mL) | R5: H2O2 A390 | S5: H2O2 (µmol/g FW) | T5: Sug leaf FW (g) | U5: Sug extract (mL) | V5: Sug dilution factor | W5: Sug A620 | X5: Soluble sugars (mg/g FW) | Y5: Prot leaf FW (g) | Z5: Prot extract (mL) | AA5: Prot A660 | AB5: Protein in extract (mg/mL) | AC5: Soluble protein (mg/g FW)
A6: EX | B6: EXAMPLE (delete) | C6: EXAMPLE | D6: 150 | E6: 0 | F6: 0.5 | G6: 0.42 | H6: 4 | I6: =IF(OR(ISNUMBER(Std_Curves!$B$13)=FALSE()),"",IF(OR(G6=""),"",(G6-Std_Curves!$B$14)/Std_Curves!$B$13)) | J6: =IF(OR(I6="",H6="",F6=""),"",(I6*H6/115.13)/(F6/5)) | K6: 0.5 | L6: 5 | M6: 0.385 | N6: 0.042 | O6: =IF(OR(M6="",N6="",K6="",L6=""),"",((M6-N6)/155)*1000*L6/K6) -> 22.129032 | P6: 0.5 | Q6: 5 | R6: 0.31 | S6: =IF(OR(ISNUMBER(Std_Curves!$E$13)=FALSE()),"",IF(OR(R6="",P6="",Q6=""),"",((R6-Std_Curves!$E$14)/Std_Curves!$E$13)*Q6/P6)) | T6: 0.5 | U6: 10 | V6: 1 | W6: 0.455 | X6: =IF(OR(ISNUMBER(Std_Curves!$K$13)=FALSE()),"",IF(OR(W6="",T6="",U6="",V6=""),"",((W6-Std_Curves!$K$14)/Std_Curves!$K$13)*U6*V6/(T6*1000))) | Y6: 0.5 | Z6: 5 | AA6: 0.26 | AB6: =IF(OR(ISNUMBER(Std_Curves!$H$13)=FALSE()),"",IF(OR(AA6=""),"",((AA6-Std_Curves!$H$14)/Std_Curves!$H$13)/1000)) | AC6: =IF(OR(AB6="",Z6="",Y6=""),"",AB6*Z6/Y6)
A7: P01 | B7: Control | 0 mM | C7: Control | D7: 0 | E7: 1 | I7: =IF(OR(ISNUMBER(Std_Curves!$B$13)=FALSE()),"",IF(OR(G7=""),"",(G7-Std_Curves!$B$14)/Std_Curves!$B$13)) | J7: =IF(OR(I7="",H7="",F7=""),"",(I7*H7/115.13)/(F7/5)) | O7: =IF(OR(M7="",N7="",K7="",L7=""),"",((M7-N7)/155)*1000*L7/K7) | S7: =IF(OR(ISNUMBER(Std_Curves!$E$13)=FALSE()),"",IF(OR(R7="",P7="",Q7=""),"",((R7-Std_Curves!$E$14)/Std_Curves!$E$13)*Q7/P7)) | X7: =IF(OR(ISNUMBER(Std_Curves!$K$13)=FALSE()),"",IF(OR(W7="",T7="",U7="",V7=""),"",((W7-Std_Curves!$K$14)/Std_Curves!$K$13)*U7*V7/(T7*1000))) | AB7: =IF(OR(ISNUMBER(Std_Curves!$H$13)=FALSE()),"",IF(OR(AA7=""),"",((AA7-Std_Curves!$H$14)/Std_Curves!$H$13)/1000)) | AC7: =IF(OR(AB7="",Z7="",Y7=""),"",AB7*Z7/Y7)
A8: P02 | B8: Control | 0 mM | C8: Control | D8: 0 | E8: 2 | I8: =IF(OR(ISNUMBER(Std_Curves!$B$13)=FALSE()),"",IF(OR(G8=""),"",(G8-Std_Curves!$B$14)/Std_Curves!$B$13)) | J8: =IF(OR(I8="",H8="",F8=""),"",(I8*H8/115.13)/(F8/5)) | O8: =IF(OR(M8="",N8="",K8="",L8=""),"",((M8-N8)/155)*1000*L8/K8) | S8: =IF(OR(ISNUMBER(Std_Curves!$E$13)=FALSE()),"",IF(OR(R8="",P8="",Q8=""),"",((R8-Std_Curves!$E$14)/Std_Curves!$E$13)*Q8/P8)) | X8: =IF(OR(ISNUMBER(Std_Curves!$K$13)=FALSE()),"",IF(OR(W8="",T8="",U8="",V8=""),"",((W8-Std_Curves!$K$14)/Std_Curves!$K$13)*U8*V8/(T8*1000))) | AB8: =IF(OR(ISNUMBER(Std_Curves!$H$13)=FALSE()),"",IF(OR(AA8=""),"",((AA8-Std_Curves!$H$14)/Std_Curves!$H$13)/1000)) | AC8: =IF(OR(AB8="",Z8="",Y8=""),"",AB8*Z8/Y8)
A9: P03 | B9: Control | 0 mM | C9: Control | D9: 0 | E9: 3 | I9: =IF(OR(ISNUMBER(Std_Curves!$B$13)=FALSE()),"",IF(OR(G9=""),"",(G9-Std_Curves!$B$14)/Std_Curves!$B$13)) | J9: =IF(OR(I9="",H9="",F9=""),"",(I9*H9/115.13)/(F9/5)) | O9: =IF(OR(M9="",N9="",K9="",L9=""),"",((M9-N9)/155)*1000*L9/K9) | S9: =IF(OR(ISNUMBER(Std_Curves!$E$13)=FALSE()),"",IF(OR(R9="",P9="",Q9=""),"",((R9-Std_Curves!$E$14)/Std_Curves!$E$13)*Q9/P9)) | X9: =IF(OR(ISNUMBER(Std_Curves!$K$13)=FALSE()),"",IF(OR(W9="",T9="",U9="",V9=""),"",((W9-Std_Curves!$K$14)/Std_Curves!$K$13)*U9*V9/(T9*1000))) | AB9: =IF(OR(ISNUMBER(Std_Curves!$H$13)=FALSE()),"",IF(OR(AA9=""),"",((AA9-Std_Curves!$H$14)/Std_Curves!$H$13)/1000)) | AC9: =IF(OR(AB9="",Z9="",Y9=""),"",AB9*Z9/Y9)
A10: P04 | B10: Control | 0 mM | C10: Control | D10: 0 | E10: 4 | I10: =IF(OR(ISNUMBER(Std_Curves!$B$13)=FALSE()),"",IF(OR(G10=""),"",(G10-Std_Curves!$B$14)/Std_Curves!$B$13)) | J10: =IF(OR(I10="",H10="",F10=""),"",(I10*H10/115.13)/(F10/5)) | O10: =IF(OR(M10="",N10="",K10="",L10=""),"",((M10-N10)/155)*1000*L10/K10) | S10: =IF(OR(ISNUMBER(Std_Curves!$E$13)=FALSE()),"",IF(OR(R10="",P10="",Q10=""),"",((R10-Std_Curves!$E$14)/Std_Curves!$E$13)*Q10/P10)) | X10: =IF(OR(ISNUMBER(Std_Curves!$K$13)=FALSE()),"",IF(OR(W10="",T10="",U10="",V10=""),"",((W10-Std_Curves!$K$14)/Std_Curves!$K$13)*U10*V10/(T10*1000))) | AB10: =IF(OR(ISNUMBER(Std_Curves!$H$13)=FALSE()),"",IF(OR(AA10=""),"",((AA10-Std_Curves!$H$14)/Std_Curves!$H$13)/1000)) | AC10: =IF(OR(AB10="",Z10="",Y10=""),"",AB10*Z10/Y10)
A11: P05 | B11: Control | 50 mM | C11: Control | D11: 50 | E11: 1 | I11: =IF(OR(ISNUMBER(Std_Curves!$B$13)=FALSE()),"",IF(OR(G11=""),"",(G11-Std_Curves!$B$14)/Std_Curves!$B$13)) | J11: =IF(OR(I11="",H11="",F11=""),"",(I11*H11/115.13)/(F11/5)) | O11: =IF(OR(M11="",N11="",K11="",L11=""),"",((M11-N11)/155)*1000*L11/K11) | S11: =IF(OR(ISNUMBER(Std_Curves!$E$13)=FALSE()),"",IF(OR(R11="",P11="",Q11=""),"",((R11-Std_Curves!$E$14)/Std_Curves!$E$13)*Q11/P11)) | X11: =IF(OR(ISNUMBER(Std_Curves!$K$13)=FALSE()),"",IF(OR(W11="",T11="",U11="",V11=""),"",((W11-Std_Curves!$K$14)/Std_Curves!$K$13)*U11*V11/(T11*1000))) | AB11: =IF(OR(ISNUMBER(Std_Curves!$H$13)=FALSE()),"",IF(OR(AA11=""),"",((AA11-Std_Curves!$H$14)/Std_Curves!$H$13)/1000)) | AC11: =IF(OR(AB11="",Z11="",Y11=""),"",AB11*Z11/Y11)
A12: P06 | B12: Control | 50 mM | C12: Control | D12: 50 | E12: 2 | I12: =IF(OR(ISNUMBER(Std_Curves!$B$13)=FALSE()),"",IF(OR(G12=""),"",(G12-Std_Curves!$B$14)/Std_Curves!$B$13)) | J12: =IF(OR(I12="",H12="",F12=""),"",(I12*H12/115.13)/(F12/5)) | O12: =IF(OR(M12="",N12="",K12="",L12=""),"",((M12-N12)/155)*1000*L12/K12) | S12: =IF(OR(ISNUMBER(Std_Curves!$E$13)=FALSE()),"",IF(OR(R12="",P12="",Q12=""),"",((R12-Std_Curves!$E$14)/Std_Curves!$E$13)*Q12/P12)) | X12: =IF(OR(ISNUMBER(Std_Curves!$K$13)=FALSE()),"",IF(OR(W12="",T12="",U12="",V12=""),"",((W12-Std_Curves!$K$14)/Std_Curves!$K$13)*U12*V12/(T12*1000))) | AB12: =IF(OR(ISNUMBER(Std_Curves!$H$13)=FALSE()),"",IF(OR(AA12=""),"",((AA12-Std_Curves!$H$14)/Std_Curves!$H$13)/1000)) | AC12: =IF(OR(AB12="",Z12="",Y12=""),"",AB12*Z12/Y12)
A13: P07 | B13: Control | 50 mM | C13: Control | D13: 50 | E13: 3 | I13: =IF(OR(ISNUMBER(Std_Curves!$B$13)=FALSE()),"",IF(OR(G13=""),"",(G13-Std_Curves!$B$14)/Std_Curves!$B$13)) | J13: =IF(OR(I13="",H13="",F13=""),"",(I13*H13/115.13)/(F13/5)) | O13: =IF(OR(M13="",N13="",K13="",L13=""),"",((M13-N13)/155)*1000*L13/K13) | S13: =IF(OR(ISNUMBER(Std_Curves!$E$13)=FALSE()),"",IF(OR(R13="",P13="",Q13=""),"",((R13-Std_Curves!$E$14)/Std_Curves!$E$13)*Q13/P13)) | X13: =IF(OR(ISNUMBER(Std_Curves!$K$13)=FALSE()),"",IF(OR(W13="",T13="",U13="",V13=""),"",((W13-Std_Curves!$K$14)/Std_Curves!$K$13)*U13*V13/(T13*1000))) | AB13: =IF(OR(ISNUMBER(Std_Curves!$H$13)=FALSE()),"",IF(OR(AA13=""),"",((AA13-Std_Curves!$H$14)/Std_Curves!$H$13)/1000)) | AC13: =IF(OR(AB13="",Z13="",Y13=""),"",AB13*Z13/Y13)
A14: P08 | B14: Control | 50 mM | C14: Control | D14: 50 | E14: 4 | I14: =IF(OR(ISNUMBER(Std_Curves!$B$13)=FALSE()),"",IF(OR(G14=""),"",(G14-Std_Curves!$B$14)/Std_Curves!$B$13)) | J14: =IF(OR(I14="",H14="",F14=""),"",(I14*H14/115.13)/(F14/5)) | O14: =IF(OR(M14="",N14="",K14="",L14=""),"",((M14-N14)/155)*1000*L14/K14) | S14: =IF(OR(ISNUMBER(Std_Curves!$E$13)=FALSE()),"",IF(OR(R14="",P14="",Q14=""),"",((R14-Std_Curves!$E$14)/Std_Curves!$E$13)*Q14/P14)) | X14: =IF(OR(ISNUMBER(Std_Curves!$K$13)=FALSE()),"",IF(OR(W14="",T14="",U14="",V14=""),"",((W14-Std_Curves!$K$14)/Std_Curves!$K$13)*U14*V14/(T14*1000))) | AB14: =IF(OR(ISNUMBER(Std_Curves!$H$13)=FALSE()),"",IF(OR(AA14=""),"",((AA14-Std_Curves!$H$14)/Std_Curves!$H$13)/1000)) | AC14: =IF(OR(AB14="",Z14="",Y14=""),"",AB14*Z14/Y14)
A15: P09 | B15: Control | 100 mM | C15: Control | D15: 100 | E15: 1 | I15: =IF(OR(ISNUMBER(Std_Curves!$B$13)=FALSE()),"",IF(OR(G15=""),"",(G15-Std_Curves!$B$14)/Std_Curves!$B$13)) | J15: =IF(OR(I15="",H15="",F15=""),"",(I15*H15/115.13)/(F15/5)) | O15: =IF(OR(M15="",N15="",K15="",L15=""),"",((M15-N15)/155)*1000*L15/K15) | S15: =IF(OR(ISNUMBER(Std_Curves!$E$13)=FALSE()),"",IF(OR(R15="",P15="",Q15=""),"",((R15-Std_Curves!$E$14)/Std_Curves!$E$13)*Q15/P15)) | X15: =IF(OR(ISNUMBER(Std_Curves!$K$13)=FALSE()),"",IF(OR(W15="",T15="",U15="",V15=""),"",((W15-Std_Curves!$K$14)/Std_Curves!$K$13)*U15*V15/(T15*1000))) | AB15: =IF(OR(ISNUMBER(Std_Curves!$H$13)=FALSE()),"",IF(OR(AA15=""),"",((AA15-Std_Curves!$H$14)/Std_Curves!$H$13)/1000)) | AC15: =IF(OR(AB15="",Z15="",Y15=""),"",AB15*Z15/Y15)
A16: P10 | B16: Control | 100 mM | C16: Control | D16: 100 | E16: 2 | I16: =IF(OR(ISNUMBER(Std_Curves!$B$13)=FALSE()),"",IF(OR(G16=""),"",(G16-Std_Curves!$B$14)/Std_Curves!$B$13)) | J16: =IF(OR(I16="",H16="",F16=""),"",(I16*H16/115.13)/(F16/5)) | O16: =IF(OR(M16="",N16="",K16="",L16=""),"",((M16-N16)/155)*1000*L16/K16) | S16: =IF(OR(ISNUMBER(Std_Curves!$E$13)=FALSE()),"",IF(OR(R16="",P16="",Q16=""),"",((R16-Std_Curves!$E$14)/Std_Curves!$E$13)*Q16/P16)) | X16: =IF(OR(ISNUMBER(Std_Curves!$K$13)=FALSE()),"",IF(OR(W16="",T16="",U16="",V16=""),"",((W16-Std_Curves!$K$14)/Std_Curves!$K$13)*U16*V16/(T16*1000))) | AB16: =IF(OR(ISNUMBER(Std_Curves!$H$13)=FALSE()),"",IF(OR(AA16=""),"",((AA16-Std_Curves!$H$14)/Std_Curves!$H$13)/1000)) | AC16: =IF(OR(AB16="",Z16="",Y16=""),"",AB16*Z16/Y16)
A17: P11 | B17: Control | 100 mM | C17: Control | D17: 100 | E17: 3 | I17: =IF(OR(ISNUMBER(Std_Curves!$B$13)=FALSE()),"",IF(OR(G17=""),"",(G17-Std_Curves!$B$14)/Std_Curves!$B$13)) | J17: =IF(OR(I17="",H17="",F17=""),"",(I17*H17/115.13)/(F17/5)) | O17: =IF(OR(M17="",N17="",K17="",L17=""),"",((M17-N17)/155)*1000*L17/K17) | S17: =IF(OR(ISNUMBER(Std_Curves!$E$13)=FALSE()),"",IF(OR(R17="",P17="",Q17=""),"",((R17-Std_Curves!$E$14)/Std_Curves!$E$13)*Q17/P17)) | X17: =IF(OR(ISNUMBER(Std_Curves!$K$13)=FALSE()),"",IF(OR(W17="",T17="",U17="",V17=""),"",((W17-Std_Curves!$K$14)/Std_Curves!$K$13)*U17*V17/(T17*1000))) | AB17: =IF(OR(ISNUMBER(Std_Curves!$H$13)=FALSE()),"",IF(OR(AA17=""),"",((AA17-Std_Curves!$H$14)/Std_Curves!$H$13)/1000)) | AC17: =IF(OR(AB17="",Z17="",Y17=""),"",AB17*Z17/Y17)
A18: P12 | B18: Control | 100 mM | C18: Control | D18: 100 | E18: 4 | I18: =IF(OR(ISNUMBER(Std_Curves!$B$13)=FALSE()),"",IF(OR(G18=""),"",(G18-Std_Curves!$B$14)/Std_Curves!$B$13)) | J18: =IF(OR(I18="",H18="",F18=""),"",(I18*H18/115.13)/(F18/5)) | O18: =IF(OR(M18="",N18="",K18="",L18=""),"",((M18-N18)/155)*1000*L18/K18) | S18: =IF(OR(ISNUMBER(Std_Curves!$E$13)=FALSE()),"",IF(OR(R18="",P18="",Q18=""),"",((R18-Std_Curves!$E$14)/Std_Curves!$E$13)*Q18/P18)) | X18: =IF(OR(ISNUMBER(Std_Curves!$K$13)=FALSE()),"",IF(OR(W18="",T18="",U18="",V18=""),"",((W18-Std_Curves!$K$14)/Std_Curves!$K$13)*U18*V18/(T18*1000))) | AB18: =IF(OR(ISNUMBER(Std_Curves!$H$13)=FALSE()),"",IF(OR(AA18=""),"",((AA18-Std_Curves!$H$14)/Std_Curves!$H$13)/1000)) | AC18: =IF(OR(AB18="",Z18="",Y18=""),"",AB18*Z18/Y18)
... A70: P64 | B70: C4-5 | 150 mM | C70: C4-5 | D70: 150 | E70: 4 | I70: =IF(OR(ISNUMBER(Std_Curves!$B$13)=FALSE()),"",IF(OR(G70=""),"",(G70-Std_Curves!$B$14)/Std_Curves!$B$13)) | J70: =IF(OR(I70="",H70="",F70=""),"",(I70*H70/115.13)/(F70/5)) | O70: =IF(OR(M70="",N70="",K70="",L70=""),"",((M70-N70)/155)*1000*L70/K70) | S70: =IF(OR(ISNUMBER(Std_Curves!$E$13)=FALSE()),"",IF(OR(R70="",P70="",Q70=""),"",((R70-Std_Curves!$E$14)/Std_Curves!$E$13)*Q70/P70)) | X70: =IF(OR(ISNUMBER(Std_Curves!$K$13)=FALSE()),"",IF(OR(W70="",T70="",U70="",V70=""),"",((W70-Std_Curves!$K$14)/Std_Curves!$K$13)*U70*V70/(T70*1000))) | AB70: =IF(OR(ISNUMBER(Std_Curves!$H$13)=FALSE()),"",IF(OR(AA70=""),"",((AA70-Std_Curves!$H$14)/Std_Curves!$H$13)/1000)) | AC70: =IF(OR(AB70="",Z70="",Y70=""),"",AB70*Z70/Y70)

Sheet A5_Enzymes
A1: Option A | Antioxidant enzymes (cold phosphate-buffer extract; specific activity per mg protein)
A2: Protein of the enzyme extract: enter mg/mL measured on the SAME extract (Lowry/Bradford). Rates: ΔA per minute from the linear part of the trace.
A4: Design | F4: Extract | I4: SOD (NBT, A560) | N4: CAT (ΔA240) | R4: APX (ΔA290) | V4: POD (guaiacol, ΔA470)
A5: Pot ID | B5: Treatment | C5: Inoculant | D5: NaCl (mM) | E5: Rep | F5: Enz leaf FW (g) | G5: Enz extract (mL) | H5: Extract protein (mg/mL) | I5: SOD A560 control | J5: SOD A560 sample | K5: SOD enzyme vol (mL) | L5: SOD inhibition (%) | M5: SOD (U/mg protein) | N5: CAT ΔA240/min | O5: CAT reaction vol (mL) | P5: CAT enzyme vol (mL) | Q5: CAT (µmol H2O2/min/mg protein) | R5: APX ΔA290/min | S5: APX reaction vol (mL) | T5: APX enzyme vol (mL) | U5: APX (µmol ASA/min/mg protein) | V5: POD ΔA470/min | W5: POD reaction vol (mL) | X5: POD enzyme vol (mL) | Y5: POD (µmol/min/mg protein)
A6: EX | B6: EXAMPLE (delete) | C6: EXAMPLE | D6: 150 | E6: 0 | F6: 0.5 | G6: 5 | H6: 1.2 | I6: 0.82 | J6: 0.41 | K6: 0.05 | L6: =IF(OR(I6="",J6=""),"",(I6-J6)/I6*100) -> 50 | M6: =IF(OR(L6="",K6="",H6=""),"",(L6/50)/K6/H6) -> 16.666667 | N6: 0.045 | O6: 3 | P6: 0.1 | Q6: =IF(OR(N6="",O6="",P6="",H6=""),"",(N6/0.0436)*O6/P6/H6) -> 25.802752 | R6: 0.03 | S6: 3 | T6: 0.1 | U6: =IF(OR(R6="",S6="",T6="",H6=""),"",(R6/2.8)*S6/T6/H6) -> 0.26785714 | V6: 0.12 | W6: 3 | X6: 0.05 | Y6: =IF(OR(V6="",W6="",X6="",H6=""),"",(V6/26.6)*W6/X6/H6) -> 0.22556391
A7: P01 | B7: Control | 0 mM | C7: Control | D7: 0 | E7: 1 | L7: =IF(OR(I7="",J7=""),"",(I7-J7)/I7*100) | M7: =IF(OR(L7="",K7="",H7=""),"",(L7/50)/K7/H7) | Q7: =IF(OR(N7="",O7="",P7="",H7=""),"",(N7/0.0436)*O7/P7/H7) | U7: =IF(OR(R7="",S7="",T7="",H7=""),"",(R7/2.8)*S7/T7/H7) | Y7: =IF(OR(V7="",W7="",X7="",H7=""),"",(V7/26.6)*W7/X7/H7)
A8: P02 | B8: Control | 0 mM | C8: Control | D8: 0 | E8: 2 | L8: =IF(OR(I8="",J8=""),"",(I8-J8)/I8*100) | M8: =IF(OR(L8="",K8="",H8=""),"",(L8/50)/K8/H8) | Q8: =IF(OR(N8="",O8="",P8="",H8=""),"",(N8/0.0436)*O8/P8/H8) | U8: =IF(OR(R8="",S8="",T8="",H8=""),"",(R8/2.8)*S8/T8/H8) | Y8: =IF(OR(V8="",W8="",X8="",H8=""),"",(V8/26.6)*W8/X8/H8)
A9: P03 | B9: Control | 0 mM | C9: Control | D9: 0 | E9: 3 | L9: =IF(OR(I9="",J9=""),"",(I9-J9)/I9*100) | M9: =IF(OR(L9="",K9="",H9=""),"",(L9/50)/K9/H9) | Q9: =IF(OR(N9="",O9="",P9="",H9=""),"",(N9/0.0436)*O9/P9/H9) | U9: =IF(OR(R9="",S9="",T9="",H9=""),"",(R9/2.8)*S9/T9/H9) | Y9: =IF(OR(V9="",W9="",X9="",H9=""),"",(V9/26.6)*W9/X9/H9)
A10: P04 | B10: Control | 0 mM | C10: Control | D10: 0 | E10: 4 | L10: =IF(OR(I10="",J10=""),"",(I10-J10)/I10*100) | M10: =IF(OR(L10="",K10="",H10=""),"",(L10/50)/K10/H10) | Q10: =IF(OR(N10="",O10="",P10="",H10=""),"",(N10/0.0436)*O10/P10/H10) | U10: =IF(OR(R10="",S10="",T10="",H10=""),"",(R10/2.8)*S10/T10/H10) | Y10: =IF(OR(V10="",W10="",X10="",H10=""),"",(V10/26.6)*W10/X10/H10)
A11: P05 | B11: Control | 50 mM | C11: Control | D11: 50 | E11: 1 | L11: =IF(OR(I11="",J11=""),"",(I11-J11)/I11*100) | M11: =IF(OR(L11="",K11="",H11=""),"",(L11/50)/K11/H11) | Q11: =IF(OR(N11="",O11="",P11="",H11=""),"",(N11/0.0436)*O11/P11/H11) | U11: =IF(OR(R11="",S11="",T11="",H11=""),"",(R11/2.8)*S11/T11/H11) | Y11: =IF(OR(V11="",W11="",X11="",H11=""),"",(V11/26.6)*W11/X11/H11)
A12: P06 | B12: Control | 50 mM | C12: Control | D12: 50 | E12: 2 | L12: =IF(OR(I12="",J12=""),"",(I12-J12)/I12*100) | M12: =IF(OR(L12="",K12="",H12=""),"",(L12/50)/K12/H12) | Q12: =IF(OR(N12="",O12="",P12="",H12=""),"",(N12/0.0436)*O12/P12/H12) | U12: =IF(OR(R12="",S12="",T12="",H12=""),"",(R12/2.8)*S12/T12/H12) | Y12: =IF(OR(V12="",W12="",X12="",H12=""),"",(V12/26.6)*W12/X12/H12)
A13: P07 | B13: Control | 50 mM | C13: Control | D13: 50 | E13: 3 | L13: =IF(OR(I13="",J13=""),"",(I13-J13)/I13*100) | M13: =IF(OR(L13="",K13="",H13=""),"",(L13/50)/K13/H13) | Q13: =IF(OR(N13="",O13="",P13="",H13=""),"",(N13/0.0436)*O13/P13/H13) | U13: =IF(OR(R13="",S13="",T13="",H13=""),"",(R13/2.8)*S13/T13/H13) | Y13: =IF(OR(V13="",W13="",X13="",H13=""),"",(V13/26.6)*W13/X13/H13)
A14: P08 | B14: Control | 50 mM | C14: Control | D14: 50 | E14: 4 | L14: =IF(OR(I14="",J14=""),"",(I14-J14)/I14*100) | M14: =IF(OR(L14="",K14="",H14=""),"",(L14/50)/K14/H14) | Q14: =IF(OR(N14="",O14="",P14="",H14=""),"",(N14/0.0436)*O14/P14/H14) | U14: =IF(OR(R14="",S14="",T14="",H14=""),"",(R14/2.8)*S14/T14/H14) | Y14: =IF(OR(V14="",W14="",X14="",H14=""),"",(V14/26.6)*W14/X14/H14)
A15: P09 | B15: Control | 100 mM | C15: Control | D15: 100 | E15: 1 | L15: =IF(OR(I15="",J15=""),"",(I15-J15)/I15*100) | M15: =IF(OR(L15="",K15="",H15=""),"",(L15/50)/K15/H15) | Q15: =IF(OR(N15="",O15="",P15="",H15=""),"",(N15/0.0436)*O15/P15/H15) | U15: =IF(OR(R15="",S15="",T15="",H15=""),"",(R15/2.8)*S15/T15/H15) | Y15: =IF(OR(V15="",W15="",X15="",H15=""),"",(V15/26.6)*W15/X15/H15)
A16: P10 | B16: Control | 100 mM | C16: Control | D16: 100 | E16: 2 | L16: =IF(OR(I16="",J16=""),"",(I16-J16)/I16*100) | M16: =IF(OR(L16="",K16="",H16=""),"",(L16/50)/K16/H16) | Q16: =IF(OR(N16="",O16="",P16="",H16=""),"",(N16/0.0436)*O16/P16/H16) | U16: =IF(OR(R16="",S16="",T16="",H16=""),"",(R16/2.8)*S16/T16/H16) | Y16: =IF(OR(V16="",W16="",X16="",H16=""),"",(V16/26.6)*W16/X16/H16)
A17: P11 | B17: Control | 100 mM | C17: Control | D17: 100 | E17: 3 | L17: =IF(OR(I17="",J17=""),"",(I17-J17)/I17*100) | M17: =IF(OR(L17="",K17="",H17=""),"",(L17/50)/K17/H17) | Q17: =IF(OR(N17="",O17="",P17="",H17=""),"",(N17/0.0436)*O17/P17/H17) | U17: =IF(OR(R17="",S17="",T17="",H17=""),"",(R17/2.8)*S17/T17/H17) | Y17: =IF(OR(V17="",W17="",X17="",H17=""),"",(V17/26.6)*W17/X17/H17)
A18: P12 | B18: Control | 100 mM | C18: Control | D18: 100 | E18: 4 | L18: =IF(OR(I18="",J18=""),"",(I18-J18)/I18*100) | M18: =IF(OR(L18="",K18="",H18=""),"",(L18/50)/K18/H18) | Q18: =IF(OR(N18="",O18="",P18="",H18=""),"",(N18/0.0436)*O18/P18/H18) | U18: =IF(OR(R18="",S18="",T18="",H18=""),"",(R18/2.8)*S18/T18/H18) | Y18: =IF(OR(V18="",W18="",X18="",H18=""),"",(V18/26.6)*W18/X18/H18)
... A70: P64 | B70: C4-5 | 150 mM | C70: C4-5 | D70: 150 | E70: 4 | L70: =IF(OR(I70="",J70=""),"",(I70-J70)/I70*100) | M70: =IF(OR(L70="",K70="",H70=""),"",(L70/50)/K70/H70) | Q70: =IF(OR(N70="",O70="",P70="",H70=""),"",(N70/0.0436)*O70/P70/H70) | U70: =IF(OR(R70="",S70="",T70="",H70=""),"",(R70/2.8)*S70/T70/H70) | Y70: =IF(OR(V70="",W70="",X70="",H70=""),"",(V70/26.6)*W70/X70/H70)

Sheet A6_Ions
A1: Option A | Ion homeostasis in leaves and roots (dry weight basis)
A2: Na+, K+ by flame photometry; Ca2+, Mg2+ by EDTA titration or AAS (enter the result as mg/L of the digest).
A4: Design | F4: Leaf digest | I4: Leaf ions | R4: Root digest | U4: Root ions
A5: Pot ID | B5: Treatment | C5: Inoculant | D5: NaCl (mM) | E5: Rep | F5: L DW digested (g) | G5: L digest vol (mL) | H5: L dilution factor | I5: L Na reading (mg/L) | J5: L K reading (mg/L) | K5: L Ca reading (mg/L) | L5: L Mg reading (mg/L) | M5: L Na (mg/g DW) | N5: L K (mg/g DW) | O5: L Ca (mg/g DW) | P5: L Mg (mg/g DW) | Q5: L K/Na ratio (molar) | R5: R DW digested (g) | S5: R digest vol (mL) | T5: R dilution factor | U5: R Na reading (mg/L) | V5: R K reading (mg/L) | W5: R Ca reading (mg/L) | X5: R Mg reading (mg/L) | Y5: R Na (mg/g DW) | Z5: R K (mg/g DW) | AA5: R Ca (mg/g DW) | AB5: R Mg (mg/g DW) | AC5: R K/Na ratio (molar)
A6: EX | B6: EXAMPLE (delete) | C6: EXAMPLE | D6: 150 | E6: 0 | F6: 0.2 | G6: 50 | H6: 1 | I6: 48 | J6: 96 | K6: 22 | L6: 11 | M6: =IF(OR(I6="",F6="",G6="",H6=""),"",I6*G6/1000*H6/F6) -> 12 | N6: =IF(OR(J6="",F6="",G6="",H6=""),"",J6*G6/1000*H6/F6) -> 24 | O6: =IF(OR(K6="",F6="",G6="",H6=""),"",K6*G6/1000*H6/F6) -> 5.5 | P6: =IF(OR(L6="",F6="",G6="",H6=""),"",L6*G6/1000*H6/F6) -> 2.75 | Q6: =IF(OR(M6="",N6=""),"",(N6/39.1)/(M6/22.99)) -> 1.1759591 | R6: 0.2 | S6: 50 | T6: 1 | U6: 70 | V6: 52 | W6: 15 | X6: 8 | Y6: =IF(OR(U6="",R6="",S6="",T6=""),"",U6*S6/1000*T6/R6) -> 17.5 | Z6: =IF(OR(V6="",R6="",S6="",T6=""),"",V6*S6/1000*T6/R6) -> 13 | AA6: =IF(OR(W6="",R6="",S6="",T6=""),"",W6*S6/1000*T6/R6) -> 3.75 | AB6: =IF(OR(X6="",R6="",S6="",T6=""),"",X6*S6/1000*T6/R6) -> 2 | AC6: =IF(OR(Y6="",Z6=""),"",(Z6/39.1)/(Y6/22.99)) -> 0.4367848
A7: P01 | B7: Control | 0 mM | C7: Control | D7: 0 | E7: 1 | M7: =IF(OR(I7="",F7="",G7="",H7=""),"",I7*G7/1000*H7/F7) | N7: =IF(OR(J7="",F7="",G7="",H7=""),"",J7*G7/1000*H7/F7) | O7: =IF(OR(K7="",F7="",G7="",H7=""),"",K7*G7/1000*H7/F7) | P7: =IF(OR(L7="",F7="",G7="",H7=""),"",L7*G7/1000*H7/F7) | Q7: =IF(OR(M7="",N7=""),"",(N7/39.1)/(M7/22.99)) | Y7: =IF(OR(U7="",R7="",S7="",T7=""),"",U7*S7/1000*T7/R7) | Z7: =IF(OR(V7="",R7="",S7="",T7=""),"",V7*S7/1000*T7/R7) | AA7: =IF(OR(W7="",R7="",S7="",T7=""),"",W7*S7/1000*T7/R7) | AB7: =IF(OR(X7="",R7="",S7="",T7=""),"",X7*S7/1000*T7/R7) | AC7: =IF(OR(Y7="",Z7=""),"",(Z7/39.1)/(Y7/22.99))
A8: P02 | B8: Control | 0 mM | C8: Control | D8: 0 | E8: 2 | M8: =IF(OR(I8="",F8="",G8="",H8=""),"",I8*G8/1000*H8/F8) | N8: =IF(OR(J8="",F8="",G8="",H8=""),"",J8*G8/1000*H8/F8) | O8: =IF(OR(K8="",F8="",G8="",H8=""),"",K8*G8/1000*H8/F8) | P8: =IF(OR(L8="",F8="",G8="",H8=""),"",L8*G8/1000*H8/F8) | Q8: =IF(OR(M8="",N8=""),"",(N8/39.1)/(M8/22.99)) | Y8: =IF(OR(U8="",R8="",S8="",T8=""),"",U8*S8/1000*T8/R8) | Z8: =IF(OR(V8="",R8="",S8="",T8=""),"",V8*S8/1000*T8/R8) | AA8: =IF(OR(W8="",R8="",S8="",T8=""),"",W8*S8/1000*T8/R8) | AB8: =IF(OR(X8="",R8="",S8="",T8=""),"",X8*S8/1000*T8/R8) | AC8: =IF(OR(Y8="",Z8=""),"",(Z8/39.1)/(Y8/22.99))
A9: P03 | B9: Control | 0 mM | C9: Control | D9: 0 | E9: 3 | M9: =IF(OR(I9="",F9="",G9="",H9=""),"",I9*G9/1000*H9/F9) | N9: =IF(OR(J9="",F9="",G9="",H9=""),"",J9*G9/1000*H9/F9) | O9: =IF(OR(K9="",F9="",G9="",H9=""),"",K9*G9/1000*H9/F9) | P9: =IF(OR(L9="",F9="",G9="",H9=""),"",L9*G9/1000*H9/F9) | Q9: =IF(OR(M9="",N9=""),"",(N9/39.1)/(M9/22.99)) | Y9: =IF(OR(U9="",R9="",S9="",T9=""),"",U9*S9/1000*T9/R9) | Z9: =IF(OR(V9="",R9="",S9="",T9=""),"",V9*S9/1000*T9/R9) | AA9: =IF(OR(W9="",R9="",S9="",T9=""),"",W9*S9/1000*T9/R9) | AB9: =IF(OR(X9="",R9="",S9="",T9=""),"",X9*S9/1000*T9/R9) | AC9: =IF(OR(Y9="",Z9=""),"",(Z9/39.1)/(Y9/22.99))
A10: P04 | B10: Control | 0 mM | C10: Control | D10: 0 | E10: 4 | M10: =IF(OR(I10="",F10="",G10="",H10=""),"",I10*G10/1000*H10/F10) | N10: =IF(OR(J10="",F10="",G10="",H10=""),"",J10*G10/1000*H10/F10) | O10: =IF(OR(K10="",F10="",G10="",H10=""),"",K10*G10/1000*H10/F10) | P10: =IF(OR(L10="",F10="",G10="",H10=""),"",L10*G10/1000*H10/F10) | Q10: =IF(OR(M10="",N10=""),"",(N10/39.1)/(M10/22.99)) | Y10: =IF(OR(U10="",R10="",S10="",T10=""),"",U10*S10/1000*T10/R10) | Z10: =IF(OR(V10="",R10="",S10="",T10=""),"",V10*S10/1000*T10/R10) | AA10: =IF(OR(W10="",R10="",S10="",T10=""),"",W10*S10/1000*T10/R10) | AB10: =IF(OR(X10="",R10="",S10="",T10=""),"",X10*S10/1000*T10/R10) | AC10: =IF(OR(Y10="",Z10=""),"",(Z10/39.1)/(Y10/22.99))
A11: P05 | B11: Control | 50 mM | C11: Control | D11: 50 | E11: 1 | M11: =IF(OR(I11="",F11="",G11="",H11=""),"",I11*G11/1000*H11/F11) | N11: =IF(OR(J11="",F11="",G11="",H11=""),"",J11*G11/1000*H11/F11) | O11: =IF(OR(K11="",F11="",G11="",H11=""),"",K11*G11/1000*H11/F11) | P11: =IF(OR(L11="",F11="",G11="",H11=""),"",L11*G11/1000*H11/F11) | Q11: =IF(OR(M11="",N11=""),"",(N11/39.1)/(M11/22.99)) | Y11: =IF(OR(U11="",R11="",S11="",T11=""),"",U11*S11/1000*T11/R11) | Z11: =IF(OR(V11="",R11="",S11="",T11=""),"",V11*S11/1000*T11/R11) | AA11: =IF(OR(W11="",R11="",S11="",T11=""),"",W11*S11/1000*T11/R11) | AB11: =IF(OR(X11="",R11="",S11="",T11=""),"",X11*S11/1000*T11/R11) | AC11: =IF(OR(Y11="",Z11=""),"",(Z11/39.1)/(Y11/22.99))
A12: P06 | B12: Control | 50 mM | C12: Control | D12: 50 | E12: 2 | M12: =IF(OR(I12="",F12="",G12="",H12=""),"",I12*G12/1000*H12/F12) | N12: =IF(OR(J12="",F12="",G12="",H12=""),"",J12*G12/1000*H12/F12) | O12: =IF(OR(K12="",F12="",G12="",H12=""),"",K12*G12/1000*H12/F12) | P12: =IF(OR(L12="",F12="",G12="",H12=""),"",L12*G12/1000*H12/F12) | Q12: =IF(OR(M12="",N12=""),"",(N12/39.1)/(M12/22.99)) | Y12: =IF(OR(U12="",R12="",S12="",T12=""),"",U12*S12/1000*T12/R12) | Z12: =IF(OR(V12="",R12="",S12="",T12=""),"",V12*S12/1000*T12/R12) | AA12: =IF(OR(W12="",R12="",S12="",T12=""),"",W12*S12/1000*T12/R12) | AB12: =IF(OR(X12="",R12="",S12="",T12=""),"",X12*S12/1000*T12/R12) | AC12: =IF(OR(Y12="",Z12=""),"",(Z12/39.1)/(Y12/22.99))
A13: P07 | B13: Control | 50 mM | C13: Control | D13: 50 | E13: 3 | M13: =IF(OR(I13="",F13="",G13="",H13=""),"",I13*G13/1000*H13/F13) | N13: =IF(OR(J13="",F13="",G13="",H13=""),"",J13*G13/1000*H13/F13) | O13: =IF(OR(K13="",F13="",G13="",H13=""),"",K13*G13/1000*H13/F13) | P13: =IF(OR(L13="",F13="",G13="",H13=""),"",L13*G13/1000*H13/F13) | Q13: =IF(OR(M13="",N13=""),"",(N13/39.1)/(M13/22.99)) | Y13: =IF(OR(U13="",R13="",S13="",T13=""),"",U13*S13/1000*T13/R13) | Z13: =IF(OR(V13="",R13="",S13="",T13=""),"",V13*S13/1000*T13/R13) | AA13: =IF(OR(W13="",R13="",S13="",T13=""),"",W13*S13/1000*T13/R13) | AB13: =IF(OR(X13="",R13="",S13="",T13=""),"",X13*S13/1000*T13/R13) | AC13: =IF(OR(Y13="",Z13=""),"",(Z13/39.1)/(Y13/22.99))
A14: P08 | B14: Control | 50 mM | C14: Control | D14: 50 | E14: 4 | M14: =IF(OR(I14="",F14="",G14="",H14=""),"",I14*G14/1000*H14/F14) | N14: =IF(OR(J14="",F14="",G14="",H14=""),"",J14*G14/1000*H14/F14) | O14: =IF(OR(K14="",F14="",G14="",H14=""),"",K14*G14/1000*H14/F14) | P14: =IF(OR(L14="",F14="",G14="",H14=""),"",L14*G14/1000*H14/F14) | Q14: =IF(OR(M14="",N14=""),"",(N14/39.1)/(M14/22.99)) | Y14: =IF(OR(U14="",R14="",S14="",T14=""),"",U14*S14/1000*T14/R14) | Z14: =IF(OR(V14="",R14="",S14="",T14=""),"",V14*S14/1000*T14/R14) | AA14: =IF(OR(W14="",R14="",S14="",T14=""),"",W14*S14/1000*T14/R14) | AB14: =IF(OR(X14="",R14="",S14="",T14=""),"",X14*S14/1000*T14/R14) | AC14: =IF(OR(Y14="",Z14=""),"",(Z14/39.1)/(Y14/22.99))
A15: P09 | B15: Control | 100 mM | C15: Control | D15: 100 | E15: 1 | M15: =IF(OR(I15="",F15="",G15="",H15=""),"",I15*G15/1000*H15/F15) | N15: =IF(OR(J15="",F15="",G15="",H15=""),"",J15*G15/1000*H15/F15) | O15: =IF(OR(K15="",F15="",G15="",H15=""),"",K15*G15/1000*H15/F15) | P15: =IF(OR(L15="",F15="",G15="",H15=""),"",L15*G15/1000*H15/F15) | Q15: =IF(OR(M15="",N15=""),"",(N15/39.1)/(M15/22.99)) | Y15: =IF(OR(U15="",R15="",S15="",T15=""),"",U15*S15/1000*T15/R15) | Z15: =IF(OR(V15="",R15="",S15="",T15=""),"",V15*S15/1000*T15/R15) | AA15: =IF(OR(W15="",R15="",S15="",T15=""),"",W15*S15/1000*T15/R15) | AB15: =IF(OR(X15="",R15="",S15="",T15=""),"",X15*S15/1000*T15/R15) | AC15: =IF(OR(Y15="",Z15=""),"",(Z15/39.1)/(Y15/22.99))
A16: P10 | B16: Control | 100 mM | C16: Control | D16: 100 | E16: 2 | M16: =IF(OR(I16="",F16="",G16="",H16=""),"",I16*G16/1000*H16/F16) | N16: =IF(OR(J16="",F16="",G16="",H16=""),"",J16*G16/1000*H16/F16) | O16: =IF(OR(K16="",F16="",G16="",H16=""),"",K16*G16/1000*H16/F16) | P16: =IF(OR(L16="",F16="",G16="",H16=""),"",L16*G16/1000*H16/F16) | Q16: =IF(OR(M16="",N16=""),"",(N16/39.1)/(M16/22.99)) | Y16: =IF(OR(U16="",R16="",S16="",T16=""),"",U16*S16/1000*T16/R16) | Z16: =IF(OR(V16="",R16="",S16="",T16=""),"",V16*S16/1000*T16/R16) | AA16: =IF(OR(W16="",R16="",S16="",T16=""),"",W16*S16/1000*T16/R16) | AB16: =IF(OR(X16="",R16="",S16="",T16=""),"",X16*S16/1000*T16/R16) | AC16: =IF(OR(Y16="",Z16=""),"",(Z16/39.1)/(Y16/22.99))
A17: P11 | B17: Control | 100 mM | C17: Control | D17: 100 | E17: 3 | M17: =IF(OR(I17="",F17="",G17="",H17=""),"",I17*G17/1000*H17/F17) | N17: =IF(OR(J17="",F17="",G17="",H17=""),"",J17*G17/1000*H17/F17) | O17: =IF(OR(K17="",F17="",G17="",H17=""),"",K17*G17/1000*H17/F17) | P17: =IF(OR(L17="",F17="",G17="",H17=""),"",L17*G17/1000*H17/F17) | Q17: =IF(OR(M17="",N17=""),"",(N17/39.1)/(M17/22.99)) | Y17: =IF(OR(U17="",R17="",S17="",T17=""),"",U17*S17/1000*T17/R17) | Z17: =IF(OR(V17="",R17="",S17="",T17=""),"",V17*S17/1000*T17/R17) | AA17: =IF(OR(W17="",R17="",S17="",T17=""),"",W17*S17/1000*T17/R17) | AB17: =IF(OR(X17="",R17="",S17="",T17=""),"",X17*S17/1000*T17/R17) | AC17: =IF(OR(Y17="",Z17=""),"",(Z17/39.1)/(Y17/22.99))
A18: P12 | B18: Control | 100 mM | C18: Control | D18: 100 | E18: 4 | M18: =IF(OR(I18="",F18="",G18="",H18=""),"",I18*G18/1000*H18/F18) | N18: =IF(OR(J18="",F18="",G18="",H18=""),"",J18*G18/1000*H18/F18) | O18: =IF(OR(K18="",F18="",G18="",H18=""),"",K18*G18/1000*H18/F18) | P18: =IF(OR(L18="",F18="",G18="",H18=""),"",L18*G18/1000*H18/F18) | Q18: =IF(OR(M18="",N18=""),"",(N18/39.1)/(M18/22.99)) | Y18: =IF(OR(U18="",R18="",S18="",T18=""),"",U18*S18/1000*T18/R18) | Z18: =IF(OR(V18="",R18="",S18="",T18=""),"",V18*S18/1000*T18/R18) | AA18: =IF(OR(W18="",R18="",S18="",T18=""),"",W18*S18/1000*T18/R18) | AB18: =IF(OR(X18="",R18="",S18="",T18=""),"",X18*S18/1000*T18/R18) | AC18: =IF(OR(Y18="",Z18=""),"",(Z18/39.1)/(Y18/22.99))
... A70: P64 | B70: C4-5 | 150 mM | C70: C4-5 | D70: 150 | E70: 4 | M70: =IF(OR(I70="",F70="",G70="",H70=""),"",I70*G70/1000*H70/F70) | N70: =IF(OR(J70="",F70="",G70="",H70=""),"",J70*G70/1000*H70/F70) | O70: =IF(OR(K70="",F70="",G70="",H70=""),"",K70*G70/1000*H70/F70) | P70: =IF(OR(L70="",F70="",G70="",H70=""),"",L70*G70/1000*H70/F70) | Q70: =IF(OR(M70="",N70=""),"",(N70/39.1)/(M70/22.99)) | Y70: =IF(OR(U70="",R70="",S70="",T70=""),"",U70*S70/1000*T70/R70) | Z70: =IF(OR(V70="",R70="",S70="",T70=""),"",V70*S70/1000*T70/R70) | AA70: =IF(OR(W70="",R70="",S70="",T70=""),"",W70*S70/1000*T70/R70) | AB70: =IF(OR(X70="",R70="",S70="",T70=""),"",X70*S70/1000*T70/R70) | AC70: =IF(OR(Y70="",Z70=""),"",(Z70/39.1)/(Y70/22.99))

Sheet A7_GasExchange
A1: Option A (optional) | Gas exchange and chlorophyll fluorescence
A2: Only if an IRGA / fluorometer is available. Measure the youngest fully expanded leaf, 09:00-11:00 h.
A4: Design | F4: Gas exchange (IRGA) | K4: Fluorescence (30 min dark)
A5: Pot ID | B5: Treatment | C5: Inoculant | D5: NaCl (mM) | E5: Rep | F5: Pn (µmol CO2/m2/s) | G5: gs (mol H2O/m2/s) | H5: E (mmol H2O/m2/s) | I5: Ci (µmol/mol) | J5: WUE (Pn/E) | K5: F0 | L5: Fm | M5: Fv/Fm
A6: EX | B6: EXAMPLE (delete) | C6: EXAMPLE | D6: 150 | E6: 0 | F6: 14.8 | G6: 0.32 | H6: 4.6 | I6: 265 | J6: =IF(OR(F6="",H6=""),"",F6/H6) -> 3.2173913 | K6: 410 | L6: 2050 | M6: =IF(OR(K6="",L6=""),"",(L6-K6)/L6) -> 0.8
A7: P01 | B7: Control | 0 mM | C7: Control | D7: 0 | E7: 1 | J7: =IF(OR(F7="",H7=""),"",F7/H7) | M7: =IF(OR(K7="",L7=""),"",(L7-K7)/L7)
A8: P02 | B8: Control | 0 mM | C8: Control | D8: 0 | E8: 2 | J8: =IF(OR(F8="",H8=""),"",F8/H8) | M8: =IF(OR(K8="",L8=""),"",(L8-K8)/L8)
A9: P03 | B9: Control | 0 mM | C9: Control | D9: 0 | E9: 3 | J9: =IF(OR(F9="",H9=""),"",F9/H9) | M9: =IF(OR(K9="",L9=""),"",(L9-K9)/L9)
A10: P04 | B10: Control | 0 mM | C10: Control | D10: 0 | E10: 4 | J10: =IF(OR(F10="",H10=""),"",F10/H10) | M10: =IF(OR(K10="",L10=""),"",(L10-K10)/L10)
A11: P05 | B11: Control | 50 mM | C11: Control | D11: 50 | E11: 1 | J11: =IF(OR(F11="",H11=""),"",F11/H11) | M11: =IF(OR(K11="",L11=""),"",(L11-K11)/L11)
A12: P06 | B12: Control | 50 mM | C12: Control | D12: 50 | E12: 2 | J12: =IF(OR(F12="",H12=""),"",F12/H12) | M12: =IF(OR(K12="",L12=""),"",(L12-K12)/L12)
A13: P07 | B13: Control | 50 mM | C13: Control | D13: 50 | E13: 3 | J13: =IF(OR(F13="",H13=""),"",F13/H13) | M13: =IF(OR(K13="",L13=""),"",(L13-K13)/L13)
A14: P08 | B14: Control | 50 mM | C14: Control | D14: 50 | E14: 4 | J14: =IF(OR(F14="",H14=""),"",F14/H14) | M14: =IF(OR(K14="",L14=""),"",(L14-K14)/L14)
A15: P09 | B15: Control | 100 mM | C15: Control | D15: 100 | E15: 1 | J15: =IF(OR(F15="",H15=""),"",F15/H15) | M15: =IF(OR(K15="",L15=""),"",(L15-K15)/L15)
A16: P10 | B16: Control | 100 mM | C16: Control | D16: 100 | E16: 2 | J16: =IF(OR(F16="",H16=""),"",F16/H16) | M16: =IF(OR(K16="",L16=""),"",(L16-K16)/L16)
A17: P11 | B17: Control | 100 mM | C17: Control | D17: 100 | E17: 3 | J17: =IF(OR(F17="",H17=""),"",F17/H17) | M17: =IF(OR(K17="",L17=""),"",(L17-K17)/L17)
A18: P12 | B18: Control | 100 mM | C18: Control | D18: 100 | E18: 4 | J18: =IF(OR(F18="",H18=""),"",F18/H18) | M18: =IF(OR(K18="",L18=""),"",(L18-K18)/L18)
... A70: P64 | B70: C4-5 | 150 mM | C70: C4-5 | D70: 150 | E70: 4 | J70: =IF(OR(F70="",H70=""),"",F70/H70) | M70: =IF(OR(K70="",L70=""),"",(L70-K70)/L70)

Sheet B_Minimal
A1: Option B | Minimum add-on: shoot/root dry weight, MDA, proline, leaf and root Na+/K+
A2: Same 64 pots and harvest day as Option A. Proline standard curve from Std_Curves.
A4: Design | F4: Biomass | I4: MDA | N4: Proline | S4: Leaf digest | V4: Leaf ions | AA4: Root digest | AD4: Root ions
A5: Pot ID | B5: Treatment | C5: Inoculant | D5: NaCl (mM) | E5: Rep | F5: Shoot DW (g) | G5: Root DW (g) | H5: Root/shoot ratio | I5: MDA leaf FW (g) | J5: MDA extract (mL) | K5: A532 | L5: A600 | M5: MDA (nmol/g FW) | N5: Pro leaf FW (g) | O5: Pro A520 | P5: Toluene (mL) | Q5: Proline (µg/mL) | R5: Proline (µmol/g FW) | S5: L DW digested (g) | T5: L digest vol (mL) | U5: L dilution factor | V5: L Na reading (mg/L) | W5: L K reading (mg/L) | X5: L Na (mg/g DW) | Y5: L K (mg/g DW) | Z5: L K/Na ratio (molar) | AA5: R DW digested (g) | AB5: R digest vol (mL) | AC5: R dilution factor | AD5: R Na reading (mg/L) | AE5: R K reading (mg/L) | AF5: R Na (mg/g DW) | AG5: R K (mg/g DW) | AH5: R K/Na ratio (molar)
A6: EX | B6: EXAMPLE (delete) | C6: EXAMPLE | D6: 150 | E6: 0 | F6: 0.61 | G6: 0.18 | H6: =IF(OR(F6="",G6=""),"",G6/F6) -> 0.29508197 | I6: 0.5 | J6: 5 | K6: 0.385 | L6: 0.042 | M6: =IF(OR(K6="",L6="",I6="",J6=""),"",((K6-L6)/155)*1000*J6/I6) -> 22.129032 | N6: 0.5 | O6: 0.42 | P6: 4 | Q6: =IF(OR(ISNUMBER(Std_Curves!$B$13)=FALSE()),"",IF(OR(O6=""),"",(O6-Std_Curves!$B$14)/Std_Curves!$B$13)) | R6: =IF(OR(Q6="",P6="",N6=""),"",(Q6*P6/115.13)/(N6/5)) | S6: 0.2 | T6: 50 | U6: 1 | V6: 48 | W6: 96 | X6: =IF(OR(V6="",S6="",T6="",U6=""),"",V6*T6/1000*U6/S6) -> 12 | Y6: =IF(OR(W6="",S6="",T6="",U6=""),"",W6*T6/1000*U6/S6) -> 24 | Z6: =IF(OR(X6="",Y6=""),"",(Y6/39.1)/(X6/22.99)) -> 1.1759591 | AA6: 0.2 | AB6: 50 | AC6: 1 | AD6: 70 | AE6: 52 | AF6: =IF(OR(AD6="",AA6="",AB6="",AC6=""),"",AD6*AB6/1000*AC6/AA6) -> 17.5 | AG6: =IF(OR(AE6="",AA6="",AB6="",AC6=""),"",AE6*AB6/1000*AC6/AA6) -> 13 | AH6: =IF(OR(AF6="",AG6=""),"",(AG6/39.1)/(AF6/22.99)) -> 0.4367848
A7: P01 | B7: Control | 0 mM | C7: Control | D7: 0 | E7: 1 | H7: =IF(OR(F7="",G7=""),"",G7/F7) | M7: =IF(OR(K7="",L7="",I7="",J7=""),"",((K7-L7)/155)*1000*J7/I7) | Q7: =IF(OR(ISNUMBER(Std_Curves!$B$13)=FALSE()),"",IF(OR(O7=""),"",(O7-Std_Curves!$B$14)/Std_Curves!$B$13)) | R7: =IF(OR(Q7="",P7="",N7=""),"",(Q7*P7/115.13)/(N7/5)) | X7: =IF(OR(V7="",S7="",T7="",U7=""),"",V7*T7/1000*U7/S7) | Y7: =IF(OR(W7="",S7="",T7="",U7=""),"",W7*T7/1000*U7/S7) | Z7: =IF(OR(X7="",Y7=""),"",(Y7/39.1)/(X7/22.99)) | AF7: =IF(OR(AD7="",AA7="",AB7="",AC7=""),"",AD7*AB7/1000*AC7/AA7) | AG7: =IF(OR(AE7="",AA7="",AB7="",AC7=""),"",AE7*AB7/1000*AC7/AA7) | AH7: =IF(OR(AF7="",AG7=""),"",(AG7/39.1)/(AF7/22.99))
A8: P02 | B8: Control | 0 mM | C8: Control | D8: 0 | E8: 2 | H8: =IF(OR(F8="",G8=""),"",G8/F8) | M8: =IF(OR(K8="",L8="",I8="",J8=""),"",((K8-L8)/155)*1000*J8/I8) | Q8: =IF(OR(ISNUMBER(Std_Curves!$B$13)=FALSE()),"",IF(OR(O8=""),"",(O8-Std_Curves!$B$14)/Std_Curves!$B$13)) | R8: =IF(OR(Q8="",P8="",N8=""),"",(Q8*P8/115.13)/(N8/5)) | X8: =IF(OR(V8="",S8="",T8="",U8=""),"",V8*T8/1000*U8/S8) | Y8: =IF(OR(W8="",S8="",T8="",U8=""),"",W8*T8/1000*U8/S8) | Z8: =IF(OR(X8="",Y8=""),"",(Y8/39.1)/(X8/22.99)) | AF8: =IF(OR(AD8="",AA8="",AB8="",AC8=""),"",AD8*AB8/1000*AC8/AA8) | AG8: =IF(OR(AE8="",AA8="",AB8="",AC8=""),"",AE8*AB8/1000*AC8/AA8) | AH8: =IF(OR(AF8="",AG8=""),"",(AG8/39.1)/(AF8/22.99))
A9: P03 | B9: Control | 0 mM | C9: Control | D9: 0 | E9: 3 | H9: =IF(OR(F9="",G9=""),"",G9/F9) | M9: =IF(OR(K9="",L9="",I9="",J9=""),"",((K9-L9)/155)*1000*J9/I9) | Q9: =IF(OR(ISNUMBER(Std_Curves!$B$13)=FALSE()),"",IF(OR(O9=""),"",(O9-Std_Curves!$B$14)/Std_Curves!$B$13)) | R9: =IF(OR(Q9="",P9="",N9=""),"",(Q9*P9/115.13)/(N9/5)) | X9: =IF(OR(V9="",S9="",T9="",U9=""),"",V9*T9/1000*U9/S9) | Y9: =IF(OR(W9="",S9="",T9="",U9=""),"",W9*T9/1000*U9/S9) | Z9: =IF(OR(X9="",Y9=""),"",(Y9/39.1)/(X9/22.99)) | AF9: =IF(OR(AD9="",AA9="",AB9="",AC9=""),"",AD9*AB9/1000*AC9/AA9) | AG9: =IF(OR(AE9="",AA9="",AB9="",AC9=""),"",AE9*AB9/1000*AC9/AA9) | AH9: =IF(OR(AF9="",AG9=""),"",(AG9/39.1)/(AF9/22.99))
